Workbook

Sheet Timeline (5W1H)
A1: TIMELINE HỘI THAO – MÔ HÌNH 5W1H (CHI TIẾT TỪNG LƯỢT)
A2: Who – What – Where – When – Why – How
A4: Mốc cố định: Bóng né bắt đầu 10:15 (ô B8). Đấu hết vòng bảng CẢ 2 MÔN rồi mới sang bán kết + chung kết CẢ 2 MÔN.
A6: STT | B6: Bắt đầu | C6: Kết thúc | D6: Thời lượng (phút) | E6: Ai (Who) | F6: Làm gì (What) | G6: Ở đâu (Where) | H6: Tại sao (Why) | I6: Làm thế nào (How)
A7: 1 | B7: =C7-D7/1440 | C7: =B8 | D7: 10 | E7: MC + Trưởng BTC + 12 đội trưởng | F7: Khai mạc chớp nhoáng, phổ biến luật 2 môn (bóng né, kéo co) | G7: Khu vực sân khấu trung tâm | H7: Đồng bộ luật 1 lần duy nhất; đảm bảo Bóng né khởi tranh đúng 10:15 | I7: MC dẫn dắt theo kịch bản; phát tờ luật in sẵn cho 12 đội trưởng; từ phút thứ 7, TNV đưa các đội của Lượt 1 Bóng né vào vị trí đúng sân
A8: 2 | B8: 10:15 | C8: =B8+D8/1440 | D8: =IF(COUNTIF('Lịch thi đấu'!$G$13:$G$24,1)>0,10,0) | E8: 4 trọng tài chính (Sân 1–4) + 4 time-keeper + 4 TNV gọi đội | F8: Bóng né vòng bảng — Lượt 1 (4 trận song song). Sân 1: Bảng A (vòng 1) — Sân 2: Bảng B (vòng 1) — Sân 3: Bảng C (vòng 1) — Sân 4: Bảng D (vòng 1) | G8: Sân bóng né 1–4 | H8: Lấy kết quả Lượt 1 làm dữ liệu xếp hạng vòng bảng — 4 sân nên mỗi sân phụ trách trọn 1 bảng | I8: Timer 10 phút/sân; từ phút thứ 7, TNV xác nhận các đội của Lượt 2 đã có mặt tại khu chờ đúng sân
A9: 3 | B9: =C8 | C9: =B9+D9/1440 | D9: =IF(COUNTIF('Lịch thi đấu'!$G$13:$G$24,2)>0,10,0) | E9: 4 trọng tài chính (Sân 1–4) + 4 time-keeper + 4 TNV gọi đội | F9: Bóng né vòng bảng — Lượt 2 (4 trận song song). Sân 1: Bảng A (vòng 2) — Sân 2: Bảng B (vòng 2) — Sân 3: Bảng C (vòng 2) — Sân 4: Bảng D (vòng 2) | G9: Sân bóng né 1–4 | H9: Lấy kết quả Lượt 2 làm dữ liệu xếp hạng vòng bảng — 4 sân nên mỗi sân phụ trách trọn 1 bảng | I9: Timer 10 phút/sân; từ phút thứ 7, TNV xác nhận các đội của Lượt 3 đã có mặt tại khu chờ đúng sân
A10: 4 | B10: =C9 | C10: =B10+D10/1440 | D10: =IF(COUNTIF('Lịch thi đấu'!$G$13:$G$24,3)>0,10,0) | E10: 4 trọng tài chính (Sân 1–4) + 4 time-keeper + 4 TNV gọi đội | F10: Bóng né vòng bảng — Lượt 3 (4 trận song song). Sân 1: Bảng A (vòng 3) — Sân 2: Bảng B (vòng 3) — Sân 3: Bảng C (vòng 3) — Sân 4: Bảng D (vòng 3) | G10: Sân bóng né 1–4 | H10: Hoàn tất đủ 12 trận vòng bảng Bóng né trước khi sang Kéo co | I10: Timer 10 phút/sân; từ phút thứ 7, TNV thông báo và bắt đầu dẫn 12 đội di chuyển dần sang khu kéo co ngay khi kết thúc trận của đội mình
A11: 5 | B11: =C10 | C11: =B11+D11/1440 | D11: 10 | E11: TNV hậu cần + toàn bộ 12 đội | F11: Di chuyển sang khu vực kéo co, phát nước | G11: Từ khu bóng né sang khu kéo co | H11: Đảm bảo chuyển tiếp mượt giữa 2 môn, không dồn toa | I11: TNV hướng dẫn theo màu đội; dây kéo co đã dựng sẵn trước; từ phút thứ 7, xác nhận các đội của Lượt 1 Kéo co đã vào vị trí cầm dây
A12: 6 | B12: =C11 | C12: =B12+D12/1440 | D12: =IF(COUNTIF('Lịch thi đấu'!$G$25:$G$36,1)>0,10,0) | E12: 3 trọng tài chính (Dây 1–3) + 3 time-keeper + 3 TNV gọi đội | F12: Kéo co vòng bảng — Lượt 1 (3 trận song song). Dây 1: Bảng A (vòng 1) — Dây 2: Bảng B (vòng 1) — Dây 3: Bảng C (vòng 1) | G12: Khu kéo co — Dây 1–3 | H12: Lấy kết quả Lượt 1 làm dữ liệu xếp hạng vòng bảng — trận đấu xoay vòng qua 3 dây để không dây nào rảnh sớm hoặc gánh nặng hơn | I12: Timer 10 phút/dây, áp dụng luật dừng cứng khi hết giờ; từ phút thứ 7, TNV xác nhận các đội của Lượt 2 đã có mặt tại vị trí chờ
A13: 7 | B13: =C12 | C13: =B13+D13/1440 | D13: =IF(COUNTIF('Lịch thi đấu'!$G$25:$G$36,2)>0,10,0) | E13: 3 trọng tài chính (Dây 1–3) + 3 time-keeper + 3 TNV gọi đội | F13: Kéo co vòng bảng — Lượt 2 (3 trận song song). Dây 1: Bảng D (vòng 1) — Dây 2: Bảng A (vòng 2) — Dây 3: Bảng B (vòng 2) | G13: Khu kéo co — Dây 1–3 | H13: Lấy kết quả Lượt 2 làm dữ liệu xếp hạng vòng bảng — trận đấu xoay vòng qua 3 dây để không dây nào rảnh sớm hoặc gánh nặng hơn | I13: Timer 10 phút/dây, áp dụng luật dừng cứng khi hết giờ; từ phút thứ 7, TNV xác nhận các đội của Lượt 3 đã có mặt tại vị trí chờ
A14: 8 | B14: =C13 | C14: =B14+D14/1440 | D14: =IF(COUNTIF('Lịch thi đấu'!$G$25:$G$36,3)>0,10,0) | E14: 3 trọng tài chính (Dây 1–3) + 3 time-keeper + 3 TNV gọi đội | F14: Kéo co vòng bảng — Lượt 3 (3 trận song song). Dây 1: Bảng C (vòng 2) — Dây 2: Bảng D (vòng 2) — Dây 3: Bảng A (vòng 3) | G14: Khu kéo co — Dây 1–3 | H14: Lấy kết quả Lượt 3 làm dữ liệu xếp hạng vòng bảng — trận đấu xoay vòng qua 3 dây để không dây nào rảnh sớm hoặc gánh nặng hơn | I14: Timer 10 phút/dây, áp dụng luật dừng cứng khi hết giờ; từ phút thứ 7, TNV xác nhận các đội của Lượt 4 đã có mặt tại vị trí chờ
A15: 9 | B15: =C14 | C15: =B15+D15/1440 | D15: =IF(COUNTIF('Lịch thi đấu'!$G$25:$G$36,4)>0,10,0) | E15: 3 trọng tài chính (Dây 1–3) + 3 time-keeper + 3 TNV gọi đội | F15: Kéo co vòng bảng — Lượt 4 (3 trận song song). Dây 1: Bảng B (vòng 3) — Dây 2: Bảng C (vòng 3) — Dây 3: Bảng D (vòng 3) | G15: Khu kéo co — Dây 1–3 | H15: Hoàn tất đủ 12 trận vòng bảng Kéo co — kết thúc TOÀN BỘ vòng bảng của cả 2 môn | I15: Timer 10 phút/dây; từ phút thứ 7, TNV thông báo nghỉ giải lao ngắn tại chỗ, chờ BTC tổng hợp kết quả vòng bảng
A16: 10 | B16: =C15 | C16: =B16+D16/1440 | D16: 10 | E16: Ban thư ký (2 người) + BTC hậu cần | F16: Tổng hợp kết quả vòng bảng cả 2 môn, chốt danh sách đội vào bán kết | G16: Bàn điều hành / Ban thư ký | H16: Đảm bảo đúng đội — đúng bảng đấu vào bán kết trước khi công bố, tránh nhầm lẫn khi đã đấu xong toàn bộ vòng bảng | I16: Nhập nốt kết quả lượt cuối vào 'Nhập kết quả'; xem tự động tại 'Tổng kết' mục 1; MC giữ nhịp bằng giao lưu/minigame khán giả trong lúc chờ
A17: 11 | B17: =C16 | C17: =B17+D17/1440 | D17: 10 | E17: 2 trọng tài (Sân 1–2) + 2 time-keeper + 2 TNV gọi đội | F17: Bóng né — Bán kết (BK1: Nhất bảng A vs Nhất bảng B; BK2: Nhất bảng C vs Nhất bảng D) | G17: Sân bóng né 1–2 | H17: Xác định 2 đội vào chung kết Bóng né — dùng đúng 2 sân hiện có, không dư không thiếu | I17: Timer 10 phút/sân; từ phút thứ 7, TNV xác nhận 4 đội Bán kết Kéo co đã có mặt tại khu kéo co để chạy nối tiếp ngay sau đó
A18: 12 | B18: =C17 | C18: =B18+D18/1440 | D18: 10 | E18: 2 trọng tài (Dây 1–2) + 2 time-keeper + 2 TNV gọi đội | F18: Kéo co — Bán kết (BK1: Nhất bảng A vs Nhất bảng B; BK2: Nhất bảng C vs Nhất bảng D) | G18: Khu kéo co — Dây 1–2 (Dây 3 để trống) | H18: Xác định 2 đội vào chung kết Kéo co | I18: Timer 10 phút/dây; từ phút thứ 7, TNV thông báo nghỉ ngắn tại chỗ chờ BTC tổng hợp kết quả bán kết cả 2 môn
A19: 13 | B19: =C18 | C19: =B19+D19/1440 | D19: 10 | E19: Ban thư ký + BTC hậu cần | F19: Tổng hợp kết quả bán kết cả 2 môn, chốt danh sách đội vào chung kết | G19: Bàn điều hành / Ban thư ký | H19: Đảm bảo đúng đội vào chung kết trước khi công bố | I19: Nhập vào 'Nhập kết quả'; xem tự động tại 'Tổng kết' mục 3; MC hâm nóng không khí, mời khán giả tập trung quanh sân trung tâm
A20: 14 | B20: =C19 | C20: =B20+D20/1440 | D20: 10 | E20: 1 trọng tài chính + 1 time-keeper + toàn bộ TNV hỗ trợ khán giả | F20: Chung kết Bóng né | G20: Sân bóng né 1 (sân trung tâm) | H20: Xác định đội vô địch Bóng né | I20: Timer 10 phút; MC tường thuật trực tiếp tạo không khí; từ phút thứ 7, TNV xác nhận 2 đội Chung kết Kéo co đã có mặt sẵn sàng
A21: 15 | B21: =C20 | C21: =B21+D21/1440 | D21: 10 | E21: 1 trọng tài chính + 1 time-keeper + toàn bộ TNV hỗ trợ khán giả | F21: Chung kết Kéo co | G21: Khu kéo co — Dây 1 (khu trung tâm) | H21: Xác định đội vô địch Kéo co | I21: Timer 10 phút; MC tường thuật trực tiếp, khuấy động khán giả 2 bên
A22: 16 | B22: =C21 | C22: =B22+D22/1440 | D22: 15 | E22: Ban thư ký + Ban hậu cần khen thưởng | F22: Chốt kết quả vô địch 2 môn; CHUẨN BỊ BẰNG KHEN, CÚP, PHẦN THƯỞNG đúng thứ tự Nhất – Nhì – Ba của từng môn | G22: Bàn điều hành + khu hậu cần trao giải (cạnh sân khấu) | H22: Tránh lúng túng, gọi nhầm tên hoặc thiếu/lộn phần thưởng khi trao giải trên sân khấu | I22: Thư ký chốt danh sách xếp hạng cuối cùng từ 'Tổng kết'; hậu cần xếp bằng khen/cúp theo đúng thứ tự MC sẽ xướng tên; kiểm đếm đủ số lượng trước khi mang lên sân khấu
A23: 17 | B23: =C22 | C23: =B23+D23/1440 | D23: 15 | E23: MC + Ban giám khảo + đại diện công ty | F23: Trao giải Vô địch Bóng né, Vô địch Kéo co + chụp ảnh lưu niệm | G23: Khu vực sân khấu trung tâm | H23: Vinh danh các đội, tạo dấu ấn kết thúc chương trình | I23: MC xướng tên đúng thứ tự đã chuẩn bị ở bước trước; trao cúp/bằng khen từng đội; chụp ảnh toàn đoàn
A24: 18 | B24: =C23 | C24: =B24+D24/1440 | D24: 15 | E24: Toàn bộ BTC | F24: Dự phòng xử lý phát sinh (trễ giờ, thời tiết, sự cố kỹ thuật) | G24: Toàn khu vực | H24: Hấp thụ rủi ro trễ giờ tích lũy trong suốt chương trình | I24: Chỉ dùng khi có phát sinh

Sheet Lịch thi đấu
A1: LỊCH THI ĐẤU — BÓNG NÉ & KÉO CO
A2: 4 sân bóng né (1 sân/bảng, 3 lượt) + 3 dây kéo co (xoay vòng, 4 lượt). Đấu hết vòng bảng CẢ 2 MÔN rồi mới sang Bán kết + Chung kết CẢ 2 MÔN — 15 trận/môn. Đổi cột "Lượt"/"Sân-Dây" nếu venue thay đổi (vd chỉ còn 2 sân bóng né, xem sheet dự phòng).
A4: Danh sách đội theo bảng (chỉnh sửa tên đội tại đây — lịch thi đấu bên dưới sẽ tự cập nhật)
A5: Bảng | B5: Vị trí 1 | C5: Vị trí 2 | D5: Vị trí 3
A6: Bảng A | B6: Đội 10 | C6: Đội 4 | D6: Đội 5
A7: Bảng B | B7: Đội 12 | C7: Đội 1 | D7: Đội 2
A8: Bảng C | B8: Đội 9 | C8: Đội 3 | D8: Đội 8
A9: Bảng D | B9: Đội 6 | C9: Đội 7 | D9: Đội 11
G11: Cột G (Lượt) màu xanh — sửa số này khi đổi số sân/dây, giờ sẽ tự tính lại
A12: STT | B12: Môn | C12: Giai đoạn | D12: Sân/Dây | E12: Đội 1 | F12: Đội 2 | G12: Lượt | H12: Giờ bắt đầu | I12: Giờ kết thúc | J12: Trạng thái | K12: Đội thắng | L12: Đang thi đấu?
A13: 1 | B13: Bóng né | C13: Vòng bảng — Bảng A (vòng 1) | D13: Sân 1 | E13: =B6 | F13: =C6 | G13: 1 | H13: ='Timeline (5W1H)'!$B$8+(G13-1)*10/1440 | I13: =H13+10/1440 | J13: =IF(INDEX('Nhập kết quả'!$I:$I,MATCH(A13,'Nhập kết quả'!$A:$A,0))="","Chưa đấu","Đã đấu xong") | K13: =INDEX('Nhập kết quả'!$I:$I,MATCH(A13,'Nhập kết quả'!$A:$A,0)) | L13: =INDEX('Nhập kết quả'!$L:$L,MATCH(A13,'Nhập kết quả'!$A:$A,0))
A14: 2 | B14: Bóng né | C14: Vòng bảng — Bảng B (vòng 1) | D14: Sân 2 | E14: =B7 | F14: =C7 | G14: 1 | H14: ='Timeline (5W1H)'!$B$8+(G14-1)*10/1440 | I14: =H14+10/1440 | J14: =IF(INDEX('Nhập kết quả'!$I:$I,MATCH(A14,'Nhập kết quả'!$A:$A,0))="","Chưa đấu","Đã đấu xong") | K14: =INDEX('Nhập kết quả'!$I:$I,MATCH(A14,'Nhập kết quả'!$A:$A,0)) | L14: =INDEX('Nhập kết quả'!$L:$L,MATCH(A14,'Nhập kết quả'!$A:$A,0))
A15: 3 | B15: Bóng né | C15: Vòng bảng — Bảng C (vòng 1) | D15: Sân 3 | E15: =B8 | F15: =C8 | G15: 1 | H15: ='Timeline (5W1H)'!$B$8+(G15-1)*10/1440 | I15: =H15+10/1440 | J15: =IF(INDEX('Nhập kết quả'!$I:$I,MATCH(A15,'Nhập kết quả'!$A:$A,0))="","Chưa đấu","Đã đấu xong") | K15: =INDEX('Nhập kết quả'!$I:$I,MATCH(A15,'Nhập kết quả'!$A:$A,0)) | L15: =INDEX('Nhập kết quả'!$L:$L,MATCH(A15,'Nhập kết quả'!$A:$A,0))
A16: 4 | B16: Bóng né | C16: Vòng bảng — Bảng D (vòng 1) | D16: Sân 4 | E16: =B9 | F16: =C9 | G16: 1 | H16: ='Timeline (5W1H)'!$B$8+(G16-1)*10/1440 | I16: =H16+10/1440 | J16: =IF(INDEX('Nhập kết quả'!$I:$I,MATCH(A16,'Nhập kết quả'!$A:$A,0))="","Chưa đấu","Đã đấu xong") | K16: =INDEX('Nhập kết quả'!$I:$I,MATCH(A16,'Nhập kết quả'!$A:$A,0)) | L16: =INDEX('Nhập kết quả'!$L:$L,MATCH(A16,'Nhập kết quả'!$A:$A,0))
A17: 5 | B17: Bóng né | C17: Vòng bảng — Bảng A (vòng 2) | D17: Sân 1 | E17: =B6 | F17: =D6 | G17: 2 | H17: ='Timeline (5W1H)'!$B$8+(G17-1)*10/1440 | I17: =H17+10/1440 | J17: =IF(INDEX('Nhập kết quả'!$I:$I,MATCH(A17,'Nhập kết quả'!$A:$A,0))="","Chưa đấu","Đã đấu xong") | K17: =INDEX('Nhập kết quả'!$I:$I,MATCH(A17,'Nhập kết quả'!$A:$A,0)) | L17: =INDEX('Nhập kết quả'!$L:$L,MATCH(A17,'Nhập kết quả'!$A:$A,0))
A18: 6 | B18: Bóng né | C18: Vòng bảng — Bảng B (vòng 2) | D18: Sân 2 | E18: =B7 | F18: =D7 | G18: 2 | H18: ='Timeline (5W1H)'!$B$8+(G18-1)*10/1440 | I18: =H18+10/1440 | J18: =IF(INDEX('Nhập kết quả'!$I:$I,MATCH(A18,'Nhập kết quả'!$A:$A,0))="","Chưa đấu","Đã đấu xong") | K18: =INDEX('Nhập kết quả'!$I:$I,MATCH(A18,'Nhập kết quả'!$A:$A,0)) | L18: =INDEX('Nhập kết quả'!$L:$L,MATCH(A18,'Nhập kết quả'!$A:$A,0))
A19: 7 | B19: Bóng né | C19: Vòng bảng — Bảng C (vòng 2) | D19: Sân 3 | E19: =B8 | F19: =D8 | G19: 2 | H19: ='Timeline (5W1H)'!$B$8+(G19-1)*10/1440 | I19: =H19+10/1440 | J19: =IF(INDEX('Nhập kết quả'!$I:$I,MATCH(A19,'Nhập kết quả'!$A:$A,0))="","Chưa đấu","Đã đấu xong") | K19: =INDEX('Nhập kết quả'!$I:$I,MATCH(A19,'Nhập kết quả'!$A:$A,0)) | L19: =INDEX('Nhập kết quả'!$L:$L,MATCH(A19,'Nhập kết quả'!$A:$A,0))
A20: 8 | B20: Bóng né | C20: Vòng bảng — Bảng D (vòng 2) | D20: Sân 4 | E20: =B9 | F20: =D9 | G20: 2 | H20: ='Timeline (5W1H)'!$B$8+(G20-1)*10/1440 | I20: =H20+10/1440 | J20: =IF(INDEX('Nhập kết quả'!$I:$I,MATCH(A20,'Nhập kết quả'!$A:$A,0))="","Chưa đấu","Đã đấu xong") | K20: =INDEX('Nhập kết quả'!$I:$I,MATCH(A20,'Nhập kết quả'!$A:$A,0)) | L20: =INDEX('Nhập kết quả'!$L:$L,MATCH(A20,'Nhập kết quả'!$A:$A,0))
A21: 9 | B21: Bóng né | C21: Vòng bảng — Bảng A (vòng 3) | D21: Sân 1 | E21: =C6 | F21: =D6 | G21: 3 | H21: ='Timeline (5W1H)'!$B$8+(G21-1)*10/1440 | I21: =H21+10/1440 | J21: =IF(INDEX('Nhập kết quả'!$I:$I,MATCH(A21,'Nhập kết quả'!$A:$A,0))="","Chưa đấu","Đã đấu xong") | K21: =INDEX('Nhập kết quả'!$I:$I,MATCH(A21,'Nhập kết quả'!$A:$A,0)) | L21: =INDEX('Nhập kết quả'!$L:$L,MATCH(A21,'Nhập kết quả'!$A:$A,0))
A22: 10 | B22: Bóng né | C22: Vòng bảng — Bảng B (vòng 3) | D22: Sân 2 | E22: =C7 | F22: =D7 | G22: 3 | H22: ='Timeline (5W1H)'!$B$8+(G22-1)*10/1440 | I22: =H22+10/1440 | J22: =IF(INDEX('Nhập kết quả'!$I:$I,MATCH(A22,'Nhập kết quả'!$A:$A,0))="","Chưa đấu","Đã đấu xong") | K22: =INDEX('Nhập kết quả'!$I:$I,MATCH(A22,'Nhập kết quả'!$A:$A,0)) | L22: =INDEX('Nhập kết quả'!$L:$L,MATCH(A22,'Nhập kết quả'!$A:$A,0))
A23: 11 | B23: Bóng né | C23: Vòng bảng — Bảng C (vòng 3) | D23: Sân 3 | E23: =C8 | F23: =D8 | G23: 3 | H23: ='Timeline (5W1H)'!$B$8+(G23-1)*10/1440 | I23: =H23+10/1440 | J23: =IF(INDEX('Nhập kết quả'!$I:$I,MATCH(A23,'Nhập kết quả'!$A:$A,0))="","Chưa đấu","Đã đấu xong") | K23: =INDEX('Nhập kết quả'!$I:$I,MATCH(A23,'Nhập kết quả'!$A:$A,0)) | L23: =INDEX('Nhập kết quả'!$L:$L,MATCH(A23,'Nhập kết quả'!$A:$A,0))
A24: 12 | B24: Bóng né | C24: Vòng bảng — Bảng D (vòng 3) | D24: Sân 4 | E24: =C9 | F24: =D9 | G24: 3 | H24: ='Timeline (5W1H)'!$B$8+(G24-1)*10/1440 | I24: =H24+10/1440 | J24: =IF(INDEX('Nhập kết quả'!$I:$I,MATCH(A24,'Nhập kết quả'!$A:$A,0))="","Chưa đấu","Đã đấu xong") | K24: =INDEX('Nhập kết quả'!$I:$I,MATCH(A24,'Nhập kết quả'!$A:$A,0)) | L24: =INDEX('Nhập kết quả'!$L:$L,MATCH(A24,'Nhập kết quả'!$A:$A,0))
A25: 13 | B25: Kéo co | C25: Vòng bảng — Bảng A (vòng 1) | D25: Dây 1 | E25: =B6 | F25: =C6 | G25: 1 | H25: ='Timeline (5W1H)'!$B$12+(G25-1)*10/1440 | I25: =H25+10/1440 | J25: =IF(INDEX('Nhập kết quả'!$I:$I,MATCH(A25,'Nhập kết quả'!$A:$A,0))="","Chưa đấu","Đã đấu xong") | K25: =INDEX('Nhập kết quả'!$I:$I,MATCH(A25,'Nhập kết quả'!$A:$A,0)) | L25: =INDEX('Nhập kết quả'!$L:$L,MATCH(A25,'Nhập kết quả'!$A:$A,0))
A26: 14 | B26: Kéo co | C26: Vòng bảng — Bảng B (vòng 1) | D26: Dây 2 | E26: =B7 | F26: =C7 | G26: 1 | H26: ='Timeline (5W1H)'!$B$12+(G26-1)*10/1440 | I26: =H26+10/1440 | J26: =IF(INDEX('Nhập kết quả'!$I:$I,MATCH(A26,'Nhập kết quả'!$A:$A,0))="","Chưa đấu","Đã đấu xong") | K26: =INDEX('Nhập kết quả'!$I:$I,MATCH(A26,'Nhập kết quả'!$A:$A,0)) | L26: =INDEX('Nhập kết quả'!$L:$L,MATCH(A26,'Nhập kết quả'!$A:$A,0))
A27: 15 | B27: Kéo co | C27: Vòng bảng — Bảng C (vòng 1) | D27: Dây 3 | E27: =B8 | F27: =C8 | G27: 1 | H27: ='Timeline (5W1H)'!$B$12+(G27-1)*10/1440 | I27: =H27+10/1440 | J27: =IF(INDEX('Nhập kết quả'!$I:$I,MATCH(A27,'Nhập kết quả'!$A:$A,0))="","Chưa đấu","Đã đấu xong") | K27: =INDEX('Nhập kết quả'!$I:$I,MATCH(A27,'Nhập kết quả'!$A:$A,0)) | L27: =INDEX('Nhập kết quả'!$L:$L,MATCH(A27,'Nhập kết quả'!$A:$A,0))
A28: 16 | B28: Kéo co | C28: Vòng bảng — Bảng D (vòng 1) | D28: Dây 1 | E28: =B9 | F28: =C9 | G28: 2 | H28: ='Timeline (5W1H)'!$B$12+(G28-1)*10/1440 | I28: =H28+10/1440 | J28: =IF(INDEX('Nhập kết quả'!$I:$I,MATCH(A28,'Nhập kết quả'!$A:$A,0))="","Chưa đấu","Đã đấu xong") | K28: =INDEX('Nhập kết quả'!$I:$I,MATCH(A28,'Nhập kết quả'!$A:$A,0)) | L28: =INDEX('Nhập kết quả'!$L:$L,MATCH(A28,'Nhập kết quả'!$A:$A,0))
A29: 17 | B29: Kéo co | C29: Vòng bảng — Bảng A (vòng 2) | D29: Dây 2 | E29: =B6 | F29: =D6 | G29: 2 | H29: ='Timeline (5W1H)'!$B$12+(G29-1)*10/1440 | I29: =H29+10/1440 | J29: =IF(INDEX('Nhập kết quả'!$I:$I,MATCH(A29,'Nhập kết quả'!$A:$A,0))="","Chưa đấu","Đã đấu xong") | K29: =INDEX('Nhập kết quả'!$I:$I,MATCH(A29,'Nhập kết quả'!$A:$A,0)) | L29: =INDEX('Nhập kết quả'!$L:$L,MATCH(A29,'Nhập kết quả'!$A:$A,0))
A30: 18 | B30: Kéo co | C30: Vòng bảng — Bảng B (vòng 2) | D30: Dây 3 | E30: =B7 | F30: =D7 | G30: 2 | H30: ='Timeline (5W1H)'!$B$12+(G30-1)*10/1440 | I30: =H30+10/1440 | J30: =IF(INDEX('Nhập kết quả'!$I:$I,MATCH(A30,'Nhập kết quả'!$A:$A,0))="","Chưa đấu","Đã đấu xong") | K30: =INDEX('Nhập kết quả'!$I:$I,MATCH(A30,'Nhập kết quả'!$A:$A,0)) | L30: =INDEX('Nhập kết quả'!$L:$L,MATCH(A30,'Nhập kết quả'!$A:$A,0))
A31: 19 | B31: Kéo co | C31: Vòng bảng — Bảng C (vòng 2) | D31: Dây 1 | E31: =B8 | F31: =D8 | G31: 3 | H31: ='Timeline (5W1H)'!$B$12+(G31-1)*10/1440 | I31: =H31+10/1440 | J31: =IF(INDEX('Nhập kết quả'!$I:$I,MATCH(A31,'Nhập kết quả'!$A:$A,0))="","Chưa đấu","Đã đấu xong") | K31: =INDEX('Nhập kết quả'!$I:$I,MATCH(A31,'Nhập kết quả'!$A:$A,0)) | L31: =INDEX('Nhập kết quả'!$L:$L,MATCH(A31,'Nhập kết quả'!$A:$A,0))
A32: 20 | B32: Kéo co | C32: Vòng bảng — Bảng D (vòng 2) | D32: Dây 2 | E32: =B9 | F32: =D9 | G32: 3 | H32: ='Timeline (5W1H)'!$B$12+(G32-1)*10/1440 | I32: =H32+10/1440 | J32: =IF(INDEX('Nhập kết quả'!$I:$I,MATCH(A32,'Nhập kết quả'!$A:$A,0))="","Chưa đấu","Đã đấu xong") | K32: =INDEX('Nhập kết quả'!$I:$I,MATCH(A32,'Nhập kết quả'!$A:$A,0)) | L32: =INDEX('Nhập kết quả'!$L:$L,MATCH(A32,'Nhập kết quả'!$A:$A,0))
A33: 21 | B33: Kéo co | C33: Vòng bảng — Bảng A (vòng 3) | D33: Dây 3 | E33: =C6 | F33: =D6 | G33: 3 | H33: ='Timeline (5W1H)'!$B$12+(G33-1)*10/1440 | I33: =H33+10/1440 | J33: =IF(INDEX('Nhập kết quả'!$I:$I,MATCH(A33,'Nhập kết quả'!$A:$A,0))="","Chưa đấu","Đã đấu xong") | K33: =INDEX('Nhập kết quả'!$I:$I,MATCH(A33,'Nhập kết quả'!$A:$A,0)) | L33: =INDEX('Nhập kết quả'!$L:$L,MATCH(A33,'Nhập kết quả'!$A:$A,0))
A34: 22 | B34: Kéo co | C34: Vòng bảng — Bảng B (vòng 3) | D34: Dây 1 | E34: =C7 | F34: =D7 | G34: 4 | H34: ='Timeline (5W1H)'!$B$12+(G34-1)*10/1440 | I34: =H34+10/1440 | J34: =IF(INDEX('Nhập kết quả'!$I:$I,MATCH(A34,'Nhập kết quả'!$A:$A,0))="","Chưa đấu","Đã đấu xong") | K34: =INDEX('Nhập kết quả'!$I:$I,MATCH(A34,'Nhập kết quả'!$A:$A,0)) | L34: =INDEX('Nhập kết quả'!$L:$L,MATCH(A34,'Nhập kết quả'!$A:$A,0))
A35: 23 | B35: Kéo co | C35: Vòng bảng — Bảng C (vòng 3) | D35: Dây 2 | E35: =C8 | F35: =D8 | G35: 4 | H35: ='Timeline (5W1H)'!$B$12+(G35-1)*10/1440 | I35: =H35+10/1440 | J35: =IF(INDEX('Nhập kết quả'!$I:$I,MATCH(A35,'Nhập kết quả'!$A:$A,0))="","Chưa đấu","Đã đấu xong") | K35: =INDEX('Nhập kết quả'!$I:$I,MATCH(A35,'Nhập kết quả'!$A:$A,0)) | L35: =INDEX('Nhập kết quả'!$L:$L,MATCH(A35,'Nhập kết quả'!$A:$A,0))
A36: 24 | B36: Kéo co | C36: Vòng bảng — Bảng D (vòng 3) | D36: Dây 3 | E36: =C9 | F36: =D9 | G36: 4 | H36: ='Timeline (5W1H)'!$B$12+(G36-1)*10/1440 | I36: =H36+10/1440 | J36: =IF(INDEX('Nhập kết quả'!$I:$I,MATCH(A36,'Nhập kết quả'!$A:$A,0))="","Chưa đấu","Đã đấu xong") | K36: =INDEX('Nhập kết quả'!$I:$I,MATCH(A36,'Nhập kết quả'!$A:$A,0)) | L36: =INDEX('Nhập kết quả'!$L:$L,MATCH(A36,'Nhập kết quả'!$A:$A,0))
A37: 25 | B37: Bóng né | C37: Bán kết 1 | D37: Sân 1 | E37: =INDEX('Tổng kết'!$C$6:$C$8,MATCH(1,'Tổng kết'!$I$6:$I$8,0)) | F37: =INDEX('Tổng kết'!$C$9:$C$11,MATCH(1,'Tổng kết'!$I$9:$I$11,0)) | G37: — | H37: ='Timeline (5W1H)'!$B$17 | I37: =H37+10/1440 | J37: =IF(INDEX('Nhập kết quả'!$I:$I,MATCH(A37,'Nhập kết quả'!$A:$A,0))="","Chưa đấu","Đã đấu xong") | K37: =INDEX('Nhập kết quả'!$I:$I,MATCH(A37,'Nhập kết quả'!$A:$A,0)) | L37: =INDEX('Nhập kết quả'!$L:$L,MATCH(A37,'Nhập kết quả'!$A:$A,0))
A38: 26 | B38: Bóng né | C38: Bán kết 2 | D38: Sân 2 | E38: =INDEX('Tổng kết'!$C$12:$C$14,MATCH(1,'Tổng kết'!$I$12:$I$14,0)) | F38: =INDEX('Tổng kết'!$C$15:$C$17,MATCH(1,'Tổng kết'!$I$15:$I$17,0)) | G38: — | H38: ='Timeline (5W1H)'!$B$17 | I38: =H38+10/1440 | J38: =IF(INDEX('Nhập kết quả'!$I:$I,MATCH(A38,'Nhập kết quả'!$A:$A,0))="","Chưa đấu","Đã đấu xong") | K38: =INDEX('Nhập kết quả'!$I:$I,MATCH(A38,'Nhập kết quả'!$A:$A,0)) | L38: =INDEX('Nhập kết quả'!$L:$L,MATCH(A38,'Nhập kết quả'!$A:$A,0))
A39: 27 | B39: Kéo co | C39: Bán kết 1 | D39: Dây 1 | E39: =INDEX('Tổng kết'!$C$18:$C$20,MATCH(1,'Tổng kết'!$I$18:$I$20,0)) | F39: =INDEX('Tổng kết'!$C$21:$C$23,MATCH(1,'Tổng kết'!$I$21:$I$23,0)) | G39: — | H39: ='Timeline (5W1H)'!$B$18 | I39: =H39+10/1440 | J39: =IF(INDEX('Nhập kết quả'!$I:$I,MATCH(A39,'Nhập kết quả'!$A:$A,0))="","Chưa đấu","Đã đấu xong") | K39: =INDEX('Nhập kết quả'!$I:$I,MATCH(A39,'Nhập kết quả'!$A:$A,0)) | L39: =INDEX('Nhập kết quả'!$L:$L,MATCH(A39,'Nhập kết quả'!$A:$A,0))
A40: 28 | B40: Kéo co | C40: Bán kết 2 | D40: Dây 2 | E40: =INDEX('Tổng kết'!$C$24:$C$26,MATCH(1,'Tổng kết'!$I$24:$I$26,0)) | F40: =INDEX('Tổng kết'!$C$27:$C$29,MATCH(1,'Tổng kết'!$I$27:$I$29,0)) | G40: — | H40: ='Timeline (5W1H)'!$B$18 | I40: =H40+10/1440 | J40: =IF(INDEX('Nhập kết quả'!$I:$I,MATCH(A40,'Nhập kết quả'!$A:$A,0))="","Chưa đấu","Đã đấu xong") | K40: =INDEX('Nhập kết quả'!$I:$I,MATCH(A40,'Nhập kết quả'!$A:$A,0)) | L40: =INDEX('Nhập kết quả'!$L:$L,MATCH(A40,'Nhập kết quả'!$A:$A,0))
A41: 29 | B41: Bóng né | C41: Chung kết | D41: Sân 1 | E41: ='Nhập kết quả'!I29 | F41: ='Nhập kết quả'!I30 | G41: — | H41: ='Timeline (5W1H)'!$B$20 | I41: =H41+10/1440 | J41: =IF(INDEX('Nhập kết quả'!$I:$I,MATCH(A41,'Nhập kết quả'!$A:$A,0))="","Chưa đấu","Đã đấu xong") | K41: =INDEX('Nhập kết quả'!$I:$I,MATCH(A41,'Nhập kết quả'!$A:$A,0)) | L41: =INDEX('Nhập kết quả'!$L:$L,MATCH(A41,'Nhập kết quả'!$A:$A,0))
A42: 30 | B42: Kéo co | C42: Chung kết | D42: Dây 1 | E42: ='Nhập kết quả'!I31 | F42: ='Nhập kết quả'!I32 | G42: — | H42: ='Timeline (5W1H)'!$B$21 | I42: =H42+10/1440 | J42: =IF(INDEX('Nhập kết quả'!$I:$I,MATCH(A42,'Nhập kết quả'!$A:$A,0))="","Chưa đấu","Đã đấu xong") | K42: =INDEX('Nhập kết quả'!$I:$I,MATCH(A42,'Nhập kết quả'!$A:$A,0)) | L42: =INDEX('Nhập kết quả'!$L:$L,MATCH(A42,'Nhập kết quả'!$A:$A,0))

Sheet Danh sách đội
A1: DANH SÁCH ĐỘI — HỘI THAO EDULYMPIC
A2: Cột "Đội" và "Bảng đấu" tự lấy từ sheet 'Lịch thi đấu' — đổi tên đội ở đó, bảng này tự cập nhật theo.
A4: STT | B4: Đội | C4: Khu vực / Khối | D4: Chi tiết địa điểm / phòng ban | E4: Bảng đấu
A5: 1 | B5: ='Lịch thi đấu'!C7 | C5: Trụ sở – Khối Sản xuất - Vận hành | D5: Sản phẩm ngoại ngữ, Đổi mới sản phẩm, Tổ chức giáo viên | E5: ='Lịch thi đấu'!$A$7
A6: 2 | B6: ='Lịch thi đấu'!D7 | C6: Trụ sở – Khối Quản trị | D6: CNTT, Nhân sự, Kế toán - Tài chính, Đào tạo | E6: ='Lịch thi đấu'!$A$7
A7: 3 | B7: ='Lịch thi đấu'!C8 | C7: Trụ sở – Khối Trải nghiệm khách hàng - hỗ trợ và truyền thông marketing | D7: Brands - marketing, Phòng Kinh doanh và Phát triển Đối tác, QLHV, Trải nghiệm khách hàng, design, CSVC | E7: ='Lịch thi đấu'!$A$8
A8: 4 | B8: ='Lịch thi đấu'!C6 | C8: Khu vực HN01 - HN05 - MB05 | D8: Đặng Thùy Trâm, Phạm Tuấn Tài 3, Láng Hạ, Mê Linh VP | E8: ='Lịch thi đấu'!$A$6
A9: 5 | B9: ='Lịch thi đấu'!D6 | C9: Khu vực HN06 - HN08 | D9: Trần Quốc Vượng, Xuân Thủy, Hoàng Quốc Việt, Bắc Từ Liêm | E9: ='Lịch thi đấu'!$A$6
A10: 6 | B10: ='Lịch thi đấu'!B9 | C10: Khu vực HN02 - MB01 | D10: Nguyễn Khuyến 1, Quang Trung, Văn Phú | E10: ='Lịch thi đấu'!$A$9
A11: 7 | B11: ='Lịch thi đấu'!C9 | C11: Khu vực HN02 - MB01 | D11: Văn Quán 1, Nguyễn Khuyến, Lê Thanh Nghị HD | E11: ='Lịch thi đấu'!$A$9
A12: 8 | B12: ='Lịch thi đấu'!D8 | C12: Khu vực HN03 - HN11 - MB02 - MT01 | D12: Thái Hà, Xuân Quỳnh, Tam Khương, Hà Huy Tập NĐ, Lê Hồng Phong NB, Phan Bội Châu NA, Lạc Long Quân TH | E12: ='Lịch thi đấu'!$A$8
A13: 9 | B13: ='Lịch thi đấu'!B8 | C13: Khu vực HN07 - MB03 | D13: Thanh Trì, Trần Đại Nghĩa 2, Lê Duẩn HP, Lạch Tray HP | E13: ='Lịch thi đấu'!$A$8
A14: 10 | B14: ='Lịch thi đấu'!B6 | C14: Khu vực HN10 - MB04 - MT02 | D14: Yên Nghĩa, Văn Quán 2, Văn Quán 3 | E14: ='Lịch thi đấu'!$A$6
A15: 11 | B15: ='Lịch thi đấu'!D9 | C15: Khu vực HN10 - MB04 - MT02 | D15: Phùng Khoang, Bắc Sơn TN, MonBay QN, Hoàng Diệu ĐN, Phong Châu TTH, Văn Quán 3 | E15: ='Lịch thi đấu'!$A$9
A16: 12 | B16: ='Lịch thi đấu'!B7 | C16: Khu vực HN15 | D16: Gia Lâm, Giải Phóng, Lê Thanh Nghị 2 | E16: ='Lịch thi đấu'!$A$7

Sheet Nhập kết quả
A1: NHẬP KẾT QUẢ THI ĐẤU
A2: Bóng né: nhập số người còn lại mỗi đội khi hết giờ | Kéo co: nhập số hiệp thắng mỗi đội (thắng 2/3).
A3: Nếu Nữ hoàng bị hạ hoặc đội phạm luật xử thua ngay: KHÔNG cần nhập chỉ số — chỉ cần chọn đội thắng ở cột "Thắng trực tiếp" (dropdown), cột Đội thắng/Đội thua sẽ tự lấy theo lựa chọn này.
A4: STT | B4: Môn | C4: Giai đoạn | D4: Đội 1 | E4: Đội 2 | F4: Chỉ số Đội 1 | G4: Chỉ số Đội 2 | H4: Thắng trực tiếp (Nữ hoàng bị hạ / phạm luật) | I4: Đội thắng | J4: Đội thua | K4: Ghi chú | L4: Đang thi đấu? | M4: Đang thi đấu (nhập tay)
A5: ='Lịch thi đấu'!A13 | B5: ='Lịch thi đấu'!B13 | C5: ='Lịch thi đấu'!C13 | D5: ='Lịch thi đấu'!E13 | E5: ='Lịch thi đấu'!F13 | I5: =IF(H5<>"",H5,IF(OR(F5="",G5=""),"",IF(F5>G5,D5,IF(G5>F5,E5,"Hòa")))) | J5: =IF(H5<>"",IF(H5=D5,E5,D5),IF(OR(F5="",G5=""),"",IF(F5>G5,E5,IF(G5>F5,D5,"Hòa")))) | L5: =IF($I5<>"","",IF($M5="Có","Có",""))
A6: ='Lịch thi đấu'!A14 | B6: ='Lịch thi đấu'!B14 | C6: ='Lịch thi đấu'!C14 | D6: ='Lịch thi đấu'!E14 | E6: ='Lịch thi đấu'!F14 | I6: =IF(H6<>"",H6,IF(OR(F6="",G6=""),"",IF(F6>G6,D6,IF(G6>F6,E6,"Hòa")))) | J6: =IF(H6<>"",IF(H6=D6,E6,D6),IF(OR(F6="",G6=""),"",IF(F6>G6,E6,IF(G6>F6,D6,"Hòa")))) | L6: =IF($I6<>"","",IF($M6="Có","Có",""))
A7: ='Lịch thi đấu'!A15 | B7: ='Lịch thi đấu'!B15 | C7: ='Lịch thi đấu'!C15 | D7: ='Lịch thi đấu'!E15 | E7: ='Lịch thi đấu'!F15 | I7: =IF(H7<>"",H7,IF(OR(F7="",G7=""),"",IF(F7>G7,D7,IF(G7>F7,E7,"Hòa")))) | J7: =IF(H7<>"",IF(H7=D7,E7,D7),IF(OR(F7="",G7=""),"",IF(F7>G7,E7,IF(G7>F7,D7,"Hòa")))) | L7: =IF($I7<>"","",IF($M7="Có","Có",""))
A8: ='Lịch thi đấu'!A16 | B8: ='Lịch thi đấu'!B16 | C8: ='Lịch thi đấu'!C16 | D8: ='Lịch thi đấu'!E16 | E8: ='Lịch thi đấu'!F16 | I8: =IF(H8<>"",H8,IF(OR(F8="",G8=""),"",IF(F8>G8,D8,IF(G8>F8,E8,"Hòa")))) | J8: =IF(H8<>"",IF(H8=D8,E8,D8),IF(OR(F8="",G8=""),"",IF(F8>G8,E8,IF(G8>F8,D8,"Hòa")))) | L8: =IF($I8<>"","",IF($M8="Có","Có",""))
A9: ='Lịch thi đấu'!A17 | B9: ='Lịch thi đấu'!B17 | C9: ='Lịch thi đấu'!C17 | D9: ='Lịch thi đấu'!E17 | E9: ='Lịch thi đấu'!F17 | I9: =IF(H9<>"",H9,IF(OR(F9="",G9=""),"",IF(F9>G9,D9,IF(G9>F9,E9,"Hòa")))) | J9: =IF(H9<>"",IF(H9=D9,E9,D9),IF(OR(F9="",G9=""),"",IF(F9>G9,E9,IF(G9>F9,D9,"Hòa")))) | L9: =IF($I9<>"","",IF($M9="Có","Có",""))
A10: ='Lịch thi đấu'!A18 | B10: ='Lịch thi đấu'!B18 | C10: ='Lịch thi đấu'!C18 | D10: ='Lịch thi đấu'!E18 | E10: ='Lịch thi đấu'!F18 | I10: =IF(H10<>"",H10,IF(OR(F10="",G10=""),"",IF(F10>G10,D10,IF(G10>F10,E10,"Hòa")))) | J10: =IF(H10<>"",IF(H10=D10,E10,D10),IF(OR(F10="",G10=""),"",IF(F10>G10,E10,IF(G10>F10,D10,"Hòa")))) | L10: =IF($I10<>"","",IF($M10="Có","Có",""))
A11: ='Lịch thi đấu'!A19 | B11: ='Lịch thi đấu'!B19 | C11: ='Lịch thi đấu'!C19 | D11: ='Lịch thi đấu'!E19 | E11: ='Lịch thi đấu'!F19 | I11: =IF(H11<>"",H11,IF(OR(F11="",G11=""),"",IF(F11>G11,D11,IF(G11>F11,E11,"Hòa")))) | J11: =IF(H11<>"",IF(H11=D11,E11,D11),IF(OR(F11="",G11=""),"",IF(F11>G11,E11,IF(G11>F11,D11,"Hòa")))) | L11: =IF($I11<>"","",IF($M11="Có","Có",""))
A12: ='Lịch thi đấu'!A20 | B12: ='Lịch thi đấu'!B20 | C12: ='Lịch thi đấu'!C20 | D12: ='Lịch thi đấu'!E20 | E12: ='Lịch thi đấu'!F20 | I12: =IF(H12<>"",H12,IF(OR(F12="",G12=""),"",IF(F12>G12,D12,IF(G12>F12,E12,"Hòa")))) | J12: =IF(H12<>"",IF(H12=D12,E12,D12),IF(OR(F12="",G12=""),"",IF(F12>G12,E12,IF(G12>F12,D12,"Hòa")))) | L12: =IF($I12<>"","",IF($M12="Có","Có",""))
A13: ='Lịch thi đấu'!A21 | B13: ='Lịch thi đấu'!B21 | C13: ='Lịch thi đấu'!C21 | D13: ='Lịch thi đấu'!E21 | E13: ='Lịch thi đấu'!F21 | I13: =IF(H13<>"",H13,IF(OR(F13="",G13=""),"",IF(F13>G13,D13,IF(G13>F13,E13,"Hòa")))) | J13: =IF(H13<>"",IF(H13=D13,E13,D13),IF(OR(F13="",G13=""),"",IF(F13>G13,E13,IF(G13>F13,D13,"Hòa")))) | L13: =IF($I13<>"","",IF($M13="Có","Có",""))
A14: ='Lịch thi đấu'!A22 | B14: ='Lịch thi đấu'!B22 | C14: ='Lịch thi đấu'!C22 | D14: ='Lịch thi đấu'!E22 | E14: ='Lịch thi đấu'!F22 | I14: =IF(H14<>"",H14,IF(OR(F14="",G14=""),"",IF(F14>G14,D14,IF(G14>F14,E14,"Hòa")))) | J14: =IF(H14<>"",IF(H14=D14,E14,D14),IF(OR(F14="",G14=""),"",IF(F14>G14,E14,IF(G14>F14,D14,"Hòa")))) | L14: =IF($I14<>"","",IF($M14="Có","Có",""))
A15: ='Lịch thi đấu'!A23 | B15: ='Lịch thi đấu'!B23 | C15: ='Lịch thi đấu'!C23 | D15: ='Lịch thi đấu'!E23 | E15: ='Lịch thi đấu'!F23 | I15: =IF(H15<>"",H15,IF(OR(F15="",G15=""),"",IF(F15>G15,D15,IF(G15>F15,E15,"Hòa")))) | J15: =IF(H15<>"",IF(H15=D15,E15,D15),IF(OR(F15="",G15=""),"",IF(F15>G15,E15,IF(G15>F15,D15,"Hòa")))) | L15: =IF($I15<>"","",IF($M15="Có","Có",""))
A16: ='Lịch thi đấu'!A24 | B16: ='Lịch thi đấu'!B24 | C16: ='Lịch thi đấu'!C24 | D16: ='Lịch thi đấu'!E24 | E16: ='Lịch thi đấu'!F24 | I16: =IF(H16<>"",H16,IF(OR(F16="",G16=""),"",IF(F16>G16,D16,IF(G16>F16,E16,"Hòa")))) | J16: =IF(H16<>"",IF(H16=D16,E16,D16),IF(OR(F16="",G16=""),"",IF(F16>G16,E16,IF(G16>F16,D16,"Hòa")))) | L16: =IF($I16<>"","",IF($M16="Có","Có",""))
... A34: ='Lịch thi đấu'!A42 | B34: ='Lịch thi đấu'!B42 | C34: ='Lịch thi đấu'!C42 | D34: ='Lịch thi đấu'!E42 | E34: ='Lịch thi đấu'!F42 | I34: =IF(H34<>"",H34,IF(OR(F34="",G34=""),"",IF(F34>G34,D34,IF(G34>F34,E34,"Hòa")))) | J34: =IF(H34<>"",IF(H34=D34,E34,D34),IF(OR(F34="",G34=""),"",IF(F34>G34,E34,IF(G34>F34,D34,"Hòa")))) | L34: =IF($I34<>"","",IF($M34="Có","Có",""))
A36: CHI TIẾT GHI BÀN — BÓNG NÉ (dùng để xét giải Cầu thủ xuất sắc nhất)
A37: Mỗi dòng = 1 người ghi bàn. Một trận có bao nhiêu người ghi bàn thì thêm bấy nhiêu dòng cùng "Trận" — không giới hạn số dòng/trận.
A39: STT | B39: Trận (Giai đoạn) | C39: Đội | D39: Tên cầu thủ | E39: Số bàn | F39: Mã tên (phụ trợ)
A40: 1 | F40: =IF(D40="","",IF(COUNTIF($D$40:D40,D40)=1,COUNT($F$39:F39)+1,""))
A41: 2 | F41: =IF(D41="","",IF(COUNTIF($D$40:D41,D41)=1,COUNT($F$39:F40)+1,""))
A42: 3 | F42: =IF(D42="","",IF(COUNTIF($D$40:D42,D42)=1,COUNT($F$39:F41)+1,""))
A43: 4 | F43: =IF(D43="","",IF(COUNTIF($D$40:D43,D43)=1,COUNT($F$39:F42)+1,""))
A44: 5 | F44: =IF(D44="","",IF(COUNTIF($D$40:D44,D44)=1,COUNT($F$39:F43)+1,""))
A45: 6 | F45: =IF(D45="","",IF(COUNTIF($D$40:D45,D45)=1,COUNT($F$39:F44)+1,""))
A46: 7 | F46: =IF(D46="","",IF(COUNTIF($D$40:D46,D46)=1,COUNT($F$39:F45)+1,""))
A47: 8 | F47: =IF(D47="","",IF(COUNTIF($D$40:D47,D47)=1,COUNT($F$39:F46)+1,""))
A48: 9 | F48: =IF(D48="","",IF(COUNTIF($D$40:D48,D48)=1,COUNT($F$39:F47)+1,""))
A49: 10 | F49: =IF(D49="","",IF(COUNTIF($D$40:D49,D49)=1,COUNT($F$39:F48)+1,""))
A50: 11 | F50: =IF(D50="","",IF(COUNTIF($D$40:D50,D50)=1,COUNT($F$39:F49)+1,""))
A51: 12 | F51: =IF(D51="","",IF(COUNTIF($D$40:D51,D51)=1,COUNT($F$39:F50)+1,""))
... A84: 45 | F84: =IF(D84="","",IF(COUNTIF($D$40:D84,D84)=1,COUNT($F$39:F83)+1,""))

Sheet Tổng kết
A1: TỔNG KẾT — BẢNG XẾP HẠNG
A2: Tự động tính từ sheet 'Nhập kết quả' — Vòng bảng: Thắng 30 – Hòa 10 – Thua 0 điểm (theo luật chính thức)
A4: 1. Xếp hạng vòng bảng theo từng môn
A5: Môn | B5: Bảng | C5: Đội | D5: Trận | E5: Thắng | F5: Hòa | G5: Thua | H5: Điểm | I5: Hạng trong bảng
A6: Bóng né | B6: Bảng A | C6: ='Lịch thi đấu'!B6 | D6: =COUNTIF('Nhập kết quả'!$D$5:$D$16,$C6)+COUNTIF('Nhập kết quả'!$E$5:$E$16,$C6) | E6: =COUNTIF('Nhập kết quả'!$I$5:$I$16,$C6) | F6: =SUMPRODUCT((('Nhập kết quả'!$D$5:$D$16=$C6)+('Nhập kết quả'!$E$5:$E$16=$C6))*('Nhập kết quả'!$I$5:$I$16="Hòa")) | G6: =COUNTIF('Nhập kết quả'!$J$5:$J$16,$C6) | H6: =E6*30+F6*10 | I6: =RANK(H6,$H$6:$H$8)
A7: Bóng né | B7: Bảng A | C7: ='Lịch thi đấu'!C6 | D7: =COUNTIF('Nhập kết quả'!$D$5:$D$16,$C7)+COUNTIF('Nhập kết quả'!$E$5:$E$16,$C7) | E7: =COUNTIF('Nhập kết quả'!$I$5:$I$16,$C7) | F7: =SUMPRODUCT((('Nhập kết quả'!$D$5:$D$16=$C7)+('Nhập kết quả'!$E$5:$E$16=$C7))*('Nhập kết quả'!$I$5:$I$16="Hòa")) | G7: =COUNTIF('Nhập kết quả'!$J$5:$J$16,$C7) | H7: =E7*30+F7*10 | I7: =RANK(H7,$H$6:$H$8)
A8: Bóng né | B8: Bảng A | C8: ='Lịch thi đấu'!D6 | D8: =COUNTIF('Nhập kết quả'!$D$5:$D$16,$C8)+COUNTIF('Nhập kết quả'!$E$5:$E$16,$C8) | E8: =COUNTIF('Nhập kết quả'!$I$5:$I$16,$C8) | F8: =SUMPRODUCT((('Nhập kết quả'!$D$5:$D$16=$C8)+('Nhập kết quả'!$E$5:$E$16=$C8))*('Nhập kết quả'!$I$5:$I$16="Hòa")) | G8: =COUNTIF('Nhập kết quả'!$J$5:$J$16,$C8) | H8: =E8*30+F8*10 | I8: =RANK(H8,$H$6:$H$8)
A9: Bóng né | B9: Bảng B | C9: ='Lịch thi đấu'!B7 | D9: =COUNTIF('Nhập kết quả'!$D$5:$D$16,$C9)+COUNTIF('Nhập kết quả'!$E$5:$E$16,$C9) | E9: =COUNTIF('Nhập kết quả'!$I$5:$I$16,$C9) | F9: =SUMPRODUCT((('Nhập kết quả'!$D$5:$D$16=$C9)+('Nhập kết quả'!$E$5:$E$16=$C9))*('Nhập kết quả'!$I$5:$I$16="Hòa")) | G9: =COUNTIF('Nhập kết quả'!$J$5:$J$16,$C9) | H9: =E9*30+F9*10 | I9: =RANK(H9,$H$9:$H$11)
A10: Bóng né | B10: Bảng B | C10: ='Lịch thi đấu'!C7 | D10: =COUNTIF('Nhập kết quả'!$D$5:$D$16,$C10)+COUNTIF('Nhập kết quả'!$E$5:$E$16,$C10) | E10: =COUNTIF('Nhập kết quả'!$I$5:$I$16,$C10) | F10: =SUMPRODUCT((('Nhập kết quả'!$D$5:$D$16=$C10)+('Nhập kết quả'!$E$5:$E$16=$C10))*('Nhập kết quả'!$I$5:$I$16="Hòa")) | G10: =COUNTIF('Nhập kết quả'!$J$5:$J$16,$C10) | H10: =E10*30+F10*10 | I10: =RANK(H10,$H$9:$H$11)
A11: Bóng né | B11: Bảng B | C11: ='Lịch thi đấu'!D7 | D11: =COUNTIF('Nhập kết quả'!$D$5:$D$16,$C11)+COUNTIF('Nhập kết quả'!$E$5:$E$16,$C11) | E11: =COUNTIF('Nhập kết quả'!$I$5:$I$16,$C11) | F11: =SUMPRODUCT((('Nhập kết quả'!$D$5:$D$16=$C11)+('Nhập kết quả'!$E$5:$E$16=$C11))*('Nhập kết quả'!$I$5:$I$16="Hòa")) | G11: =COUNTIF('Nhập kết quả'!$J$5:$J$16,$C11) | H11: =E11*30+F11*10 | I11: =RANK(H11,$H$9:$H$11)
A12: Bóng né | B12: Bảng C | C12: ='Lịch thi đấu'!B8 | D12: =COUNTIF('Nhập kết quả'!$D$5:$D$16,$C12)+COUNTIF('Nhập kết quả'!$E$5:$E$16,$C12) | E12: =COUNTIF('Nhập kết quả'!$I$5:$I$16,$C12) | F12: =SUMPRODUCT((('Nhập kết quả'!$D$5:$D$16=$C12)+('Nhập kết quả'!$E$5:$E$16=$C12))*('Nhập kết quả'!$I$5:$I$16="Hòa")) | G12: =COUNTIF('Nhập kết quả'!$J$5:$J$16,$C12) | H12: =E12*30+F12*10 | I12: =RANK(H12,$H$12:$H$14)
A13: Bóng né | B13: Bảng C | C13: ='Lịch thi đấu'!C8 | D13: =COUNTIF('Nhập kết quả'!$D$5:$D$16,$C13)+COUNTIF('Nhập kết quả'!$E$5:$E$16,$C13) | E13: =COUNTIF('Nhập kết quả'!$I$5:$I$16,$C13) | F13: =SUMPRODUCT((('Nhập kết quả'!$D$5:$D$16=$C13)+('Nhập kết quả'!$E$5:$E$16=$C13))*('Nhập kết quả'!$I$5:$I$16="Hòa")) | G13: =COUNTIF('Nhập kết quả'!$J$5:$J$16,$C13) | H13: =E13*30+F13*10 | I13: =RANK(H13,$H$12:$H$14)
A14: Bóng né | B14: Bảng C | C14: ='Lịch thi đấu'!D8 | D14: =COUNTIF('Nhập kết quả'!$D$5:$D$16,$C14)+COUNTIF('Nhập kết quả'!$E$5:$E$16,$C14) | E14: =COUNTIF('Nhập kết quả'!$I$5:$I$16,$C14) | F14: =SUMPRODUCT((('Nhập kết quả'!$D$5:$D$16=$C14)+('Nhập kết quả'!$E$5:$E$16=$C14))*('Nhập kết quả'!$I$5:$I$16="Hòa")) | G14: =COUNTIF('Nhập kết quả'!$J$5:$J$16,$C14) | H14: =E14*30+F14*10 | I14: =RANK(H14,$H$12:$H$14)
A15: Bóng né | B15: Bảng D | C15: ='Lịch thi đấu'!B9 | D15: =COUNTIF('Nhập kết quả'!$D$5:$D$16,$C15)+COUNTIF('Nhập kết quả'!$E$5:$E$16,$C15) | E15: =COUNTIF('Nhập kết quả'!$I$5:$I$16,$C15) | F15: =SUMPRODUCT((('Nhập kết quả'!$D$5:$D$16=$C15)+('Nhập kết quả'!$E$5:$E$16=$C15))*('Nhập kết quả'!$I$5:$I$16="Hòa")) | G15: =COUNTIF('Nhập kết quả'!$J$5:$J$16,$C15) | H15: =E15*30+F15*10 | I15: =RANK(H15,$H$15:$H$17)
A16: Bóng né | B16: Bảng D | C16: ='Lịch thi đấu'!C9 | D16: =COUNTIF('Nhập kết quả'!$D$5:$D$16,$C16)+COUNTIF('Nhập kết quả'!$E$5:$E$16,$C16) | E16: =COUNTIF('Nhập kết quả'!$I$5:$I$16,$C16) | F16: =SUMPRODUCT((('Nhập kết quả'!$D$5:$D$16=$C16)+('Nhập kết quả'!$E$5:$E$16=$C16))*('Nhập kết quả'!$I$5:$I$16="Hòa")) | G16: =COUNTIF('Nhập kết quả'!$J$5:$J$16,$C16) | H16: =E16*30+F16*10 | I16: =RANK(H16,$H$15:$H$17)
A17: Bóng né | B17: Bảng D | C17: ='Lịch thi đấu'!D9 | D17: =COUNTIF('Nhập kết quả'!$D$5:$D$16,$C17)+COUNTIF('Nhập kết quả'!$E$5:$E$16,$C17) | E17: =COUNTIF('Nhập kết quả'!$I$5:$I$16,$C17) | F17: =SUMPRODUCT((('Nhập kết quả'!$D$5:$D$16=$C17)+('Nhập kết quả'!$E$5:$E$16=$C17))*('Nhập kết quả'!$I$5:$I$16="Hòa")) | G17: =COUNTIF('Nhập kết quả'!$J$5:$J$16,$C17) | H17: =E17*30+F17*10 | I17: =RANK(H17,$H$15:$H$17)
A18: Kéo co | B18: Bảng A | C18: ='Lịch thi đấu'!B6 | D18: =COUNTIF('Nhập kết quả'!$D$17:$D$28,$C18)+COUNTIF('Nhập kết quả'!$E$17:$E$28,$C18) | E18: =COUNTIF('Nhập kết quả'!$I$17:$I$28,$C18) | F18: =SUMPRODUCT((('Nhập kết quả'!$D$17:$D$28=$C18)+('Nhập kết quả'!$E$17:$E$28=$C18))*('Nhập kết quả'!$I$17:$I$28="Hòa")) | G18: =COUNTIF('Nhập kết quả'!$J$17:$J$28,$C18) | H18: =E18*30+F18*10 | I18: =RANK(H18,$H$18:$H$20)
A19: Kéo co | B19: Bảng A | C19: ='Lịch thi đấu'!C6 | D19: =COUNTIF('Nhập kết quả'!$D$17:$D$28,$C19)+COUNTIF('Nhập kết quả'!$E$17:$E$28,$C19) | E19: =COUNTIF('Nhập kết quả'!$I$17:$I$28,$C19) | F19: =SUMPRODUCT((('Nhập kết quả'!$D$17:$D$28=$C19)+('Nhập kết quả'!$E$17:$E$28=$C19))*('Nhập kết quả'!$I$17:$I$28="Hòa")) | G19: =COUNTIF('Nhập kết quả'!$J$17:$J$28,$C19) | H19: =E19*30+F19*10 | I19: =RANK(H19,$H$18:$H$20)
A20: Kéo co | B20: Bảng A | C20: ='Lịch thi đấu'!D6 | D20: =COUNTIF('Nhập kết quả'!$D$17:$D$28,$C20)+COUNTIF('Nhập kết quả'!$E$17:$E$28,$C20) | E20: =COUNTIF('Nhập kết quả'!$I$17:$I$28,$C20) | F20: =SUMPRODUCT((('Nhập kết quả'!$D$17:$D$28=$C20)+('Nhập kết quả'!$E$17:$E$28=$C20))*('Nhập kết quả'!$I$17:$I$28="Hòa")) | G20: =COUNTIF('Nhập kết quả'!$J$17:$J$28,$C20) | H20: =E20*30+F20*10 | I20: =RANK(H20,$H$18:$H$20)
A21: Kéo co | B21: Bảng B | C21: ='Lịch thi đấu'!B7 | D21: =COUNTIF('Nhập kết quả'!$D$17:$D$28,$C21)+COUNTIF('Nhập kết quả'!$E$17:$E$28,$C21) | E21: =COUNTIF('Nhập kết quả'!$I$17:$I$28,$C21) | F21: =SUMPRODUCT((('Nhập kết quả'!$D$17:$D$28=$C21)+('Nhập kết quả'!$E$17:$E$28=$C21))*('Nhập kết quả'!$I$17:$I$28="Hòa")) | G21: =COUNTIF('Nhập kết quả'!$J$17:$J$28,$C21) | H21: =E21*30+F21*10 | I21: =RANK(H21,$H$21:$H$23)
A22: Kéo co | B22: Bảng B | C22: ='Lịch thi đấu'!C7 | D22: =COUNTIF('Nhập kết quả'!$D$17:$D$28,$C22)+COUNTIF('Nhập kết quả'!$E$17:$E$28,$C22) | E22: =COUNTIF('Nhập kết quả'!$I$17:$I$28,$C22) | F22: =SUMPRODUCT((('Nhập kết quả'!$D$17:$D$28=$C22)+('Nhập kết quả'!$E$17:$E$28=$C22))*('Nhập kết quả'!$I$17:$I$28="Hòa")) | G22: =COUNTIF('Nhập kết quả'!$J$17:$J$28,$C22) | H22: =E22*30+F22*10 | I22: =RANK(H22,$H$21:$H$23)
A23: Kéo co | B23: Bảng B | C23: ='Lịch thi đấu'!D7 | D23: =COUNTIF('Nhập kết quả'!$D$17:$D$28,$C23)+COUNTIF('Nhập kết quả'!$E$17:$E$28,$C23) | E23: =COUNTIF('Nhập kết quả'!$I$17:$I$28,$C23) | F23: =SUMPRODUCT((('Nhập kết quả'!$D$17:$D$28=$C23)+('Nhập kết quả'!$E$17:$E$28=$C23))*('Nhập kết quả'!$I$17:$I$28="Hòa")) | G23: =COUNTIF('Nhập kết quả'!$J$17:$J$28,$C23) | H23: =E23*30+F23*10 | I23: =RANK(H23,$H$21:$H$23)
A24: Kéo co | B24: Bảng C | C24: ='Lịch thi đấu'!B8 | D24: =COUNTIF('Nhập kết quả'!$D$17:$D$28,$C24)+COUNTIF('Nhập kết quả'!$E$17:$E$28,$C24) | E24: =COUNTIF('Nhập kết quả'!$I$17:$I$28,$C24) | F24: =SUMPRODUCT((('Nhập kết quả'!$D$17:$D$28=$C24)+('Nhập kết quả'!$E$17:$E$28=$C24))*('Nhập kết quả'!$I$17:$I$28="Hòa")) | G24: =COUNTIF('Nhập kết quả'!$J$17:$J$28,$C24) | H24: =E24*30+F24*10 | I24: =RANK(H24,$H$24:$H$26)
A25: Kéo co | B25: Bảng C | C25: ='Lịch thi đấu'!C8 | D25: =COUNTIF('Nhập kết quả'!$D$17:$D$28,$C25)+COUNTIF('Nhập kết quả'!$E$17:$E$28,$C25) | E25: =COUNTIF('Nhập kết quả'!$I$17:$I$28,$C25) | F25: =SUMPRODUCT((('Nhập kết quả'!$D$17:$D$28=$C25)+('Nhập kết quả'!$E$17:$E$28=$C25))*('Nhập kết quả'!$I$17:$I$28="Hòa")) | G25: =COUNTIF('Nhập kết quả'!$J$17:$J$28,$C25) | H25: =E25*30+F25*10 | I25: =RANK(H25,$H$24:$H$26)
A26: Kéo co | B26: Bảng C | C26: ='Lịch thi đấu'!D8 | D26: =COUNTIF('Nhập kết quả'!$D$17:$D$28,$C26)+COUNTIF('Nhập kết quả'!$E$17:$E$28,$C26) | E26: =COUNTIF('Nhập kết quả'!$I$17:$I$28,$C26) | F26: =SUMPRODUCT((('Nhập kết quả'!$D$17:$D$28=$C26)+('Nhập kết quả'!$E$17:$E$28=$C26))*('Nhập kết quả'!$I$17:$I$28="Hòa")) | G26: =COUNTIF('Nhập kết quả'!$J$17:$J$28,$C26) | H26: =E26*30+F26*10 | I26: =RANK(H26,$H$24:$H$26)
A27: Kéo co | B27: Bảng D | C27: ='Lịch thi đấu'!B9 | D27: =COUNTIF('Nhập kết quả'!$D$17:$D$28,$C27)+COUNTIF('Nhập kết quả'!$E$17:$E$28,$C27) | E27: =COUNTIF('Nhập kết quả'!$I$17:$I$28,$C27) | F27: =SUMPRODUCT((('Nhập kết quả'!$D$17:$D$28=$C27)+('Nhập kết quả'!$E$17:$E$28=$C27))*('Nhập kết quả'!$I$17:$I$28="Hòa")) | G27: =COUNTIF('Nhập kết quả'!$J$17:$J$28,$C27) | H27: =E27*30+F27*10 | I27: =RANK(H27,$H$27:$H$29)
A28: Kéo co | B28: Bảng D | C28: ='Lịch thi đấu'!C9 | D28: =COUNTIF('Nhập kết quả'!$D$17:$D$28,$C28)+COUNTIF('Nhập kết quả'!$E$17:$E$28,$C28) | E28: =COUNTIF('Nhập kết quả'!$I$17:$I$28,$C28) | F28: =SUMPRODUCT((('Nhập kết quả'!$D$17:$D$28=$C28)+('Nhập kết quả'!$E$17:$E$28=$C28))*('Nhập kết quả'!$I$17:$I$28="Hòa")) | G28: =COUNTIF('Nhập kết quả'!$J$17:$J$28,$C28) | H28: =E28*30+F28*10 | I28: =RANK(H28,$H$27:$H$29)
A29: Kéo co | B29: Bảng D | C29: ='Lịch thi đấu'!D9 | D29: =COUNTIF('Nhập kết quả'!$D$17:$D$28,$C29)+COUNTIF('Nhập kết quả'!$E$17:$E$28,$C29) | E29: =COUNTIF('Nhập kết quả'!$I$17:$I$28,$C29) | F29: =SUMPRODUCT((('Nhập kết quả'!$D$17:$D$28=$C29)+('Nhập kết quả'!$E$17:$E$28=$C29))*('Nhập kết quả'!$I$17:$I$28="Hòa")) | G29: =COUNTIF('Nhập kết quả'!$J$17:$J$28,$C29) | H29: =E29*30+F29*10 | I29: =RANK(H29,$H$27:$H$29)
A31: 2. Vòng loại trực tiếp & Vô địch mỗi môn
A32: Môn | B32: Giai đoạn | C32: Đội 1 | D32: Đội 2 | E32: Đội thắng
A33: Bóng né | B33: Bán kết 1 | C33: ='Nhập kết quả'!D29 | D33: ='Nhập kết quả'!E29 | E33: ='Nhập kết quả'!I29
A34: Bóng né | B34: Bán kết 2 | C34: ='Nhập kết quả'!D30 | D34: ='Nhập kết quả'!E30 | E34: ='Nhập kết quả'!I30
A35: Bóng né | B35: Chung kết | C35: ='Nhập kết quả'!D33 | D35: ='Nhập kết quả'!E33 | E35: ='Nhập kết quả'!I33
A36: Kéo co | B36: Bán kết 1 | C36: ='Nhập kết quả'!D31 | D36: ='Nhập kết quả'!E31 | E36: ='Nhập kết quả'!I31
A37: Kéo co | B37: Bán kết 2 | C37: ='Nhập kết quả'!D32 | D37: ='Nhập kết quả'!E32 | E37: ='Nhập kết quả'!I32
A38: Kéo co | B38: Chung kết | C38: ='Nhập kết quả'!D34 | D38: ='Nhập kết quả'!E34 | E38: ='Nhập kết quả'!I34
A40: VÔ ĐỊCH BÓNG NÉ: | B40: =E35
A41: VÔ ĐỊCH KÉO CO: | B41: =E38

Sheet Kịch bản chi tiết
A1: KỊCH BẢN VẬN HÀNH CHI TIẾT — HỘI THAO
A2: Bắt đầu/Kết thúc lấy tự động từ sheet 'Timeline (5W1H)' — đổi giờ Bóng né ở đó, bảng này tự cập nhật theo
A4: STT | B4: Tiết mục | C4: Công việc chi tiết | D4: Bắt đầu | E4: Kết thúc | F4: MC | G4: Trọng tài | H4: Thư ký ghi kết quả | I4: Người hỗ trợ (TNV) | J4: Ghi chú / thiết bị
A5: 1 | B5: Khai mạc | C5: Khai mạc chớp nhoáng, phổ biến luật 2 môn | D5: ='Timeline (5W1H)'!B7 | E5: ='Timeline (5W1H)'!C7 | F5: Dẫn dắt khai mạc, phổ biến luật; phát tờ luật in sẵn cho 12 đội trưởng | G5: 7 trọng tài (4 sân Bóng né + 3 dây Kéo co) tập trung nhận sơ đồ vị trí, đồng bộ đồng hồ | H5: Chuẩn bị file 'Nhập kết quả', kiểm tra máy tính/kết nối mạng | I5: Từ phút thứ 7, đưa các đội của Lượt 1 Bóng né vào đúng sân | J5: Loa tay từng sân/dây, đồng hồ đếm ngược, tờ luật in sẵn
A6: 2 | B6: Bóng né — Lượt 1 | C6: Vòng bảng Lượt 1, 4 trận song song: Sân 1 (Bảng A): Đội 10 (KV Yên Nghĩa/Văn Quán 2-3) vs Đội 4 (KV Đặng Thùy Trâm/Phạm Tuấn Tài 3/Láng Hạ/Mê Linh) Sân 2 (Bảng B): Đội 12 (KV Gia Lâm/Giải Phóng/Lê Thanh Nghị 2) vs Đội 1 (Trụ sở – Khối Sản xuất - Vận hành) Sân 3 (Bảng C): Đội 9 (KV Thanh Trì/Trần Đại Nghĩa 2/Lê Duẩn HP/Lạch Tray HP) vs Đội 3 (Trụ sở – Khối TNKH & Truyền thông Marketing) Sân 4 (Bảng D): Đội 6 (KV Nguyễn Khuyến 1/Quang Trung/Văn Phú) vs Đội 7 (KV Văn Quán 1/Nguyễn Khuyến/Lê Thanh Nghị HD) | D6: ='Timeline (5W1H)'!B8 | E6: ='Timeline (5W1H)'!C8 | F6: Giới thiệu nhanh cặp đấu từng sân qua loa | G6: 4 trọng tài chính bấm giờ 10 phút/sân, xử lý loại người, công bố kết quả. Trước trận: 2 đội oẳn tù xì chọn đội ném trước; sau đó trọng tài lần lượt đến từng đội (đứng quây vòng tròn kín, đối phương không nhìn thấy) để báo bí mật ai là Nữ hoàng của đội mình. | H6: Nhận kết quả từ 4 trọng tài, nhập ngay vào 'Nhập kết quả' | I6: Từ phút thứ 7, xác nhận các đội của Lượt 2 đã có mặt tại khu chờ đúng sân
A7: 3 | B7: Bóng né — Lượt 2 | C7: Vòng bảng Lượt 2, 4 trận song song: Sân 1 (Bảng A): Đội 10 (KV Yên Nghĩa/Văn Quán 2-3) vs Đội 5 (KV Trần Quốc Vượng/Xuân Thủy/Hoàng Quốc Việt/Bắc Từ Liêm) Sân 2 (Bảng B): Đội 12 (KV Gia Lâm/Giải Phóng/Lê Thanh Nghị 2) vs Đội 2 (Trụ sở – Khối Quản trị) Sân 3 (Bảng C): Đội 9 (KV Thanh Trì/Trần Đại Nghĩa 2/Lê Duẩn HP/Lạch Tray HP) vs Đội 8 (KV Thái Hà/Xuân Quỳnh/Tam Khương...) Sân 4 (Bảng D): Đội 6 (KV Nguyễn Khuyến 1/Quang Trung/Văn Phú) vs Đội 11 (KV Phùng Khoang/Bắc Sơn/MonBay/Hoàng Diệu/Phong Châu) | D7: ='Timeline (5W1H)'!B9 | E7: ='Timeline (5W1H)'!C9 | F7: Giới thiệu nhanh cặp đấu từng sân qua loa | G7: 4 trọng tài chính bấm giờ 10 phút/sân, xử lý loại người, công bố kết quả. Trước trận: 2 đội oẳn tù xì chọn đội ném trước; sau đó trọng tài lần lượt đến từng đội (đứng quây vòng tròn kín, đối phương không nhìn thấy) để báo bí mật ai là Nữ hoàng của đội mình. | H7: Nhận kết quả từ 4 trọng tài, nhập ngay vào 'Nhập kết quả' | I7: Từ phút thứ 7, xác nhận các đội của Lượt 3 đã có mặt tại khu chờ đúng sân
A8: 4 | B8: Bóng né — Lượt 3 | C8: Vòng bảng Lượt 3, 4 trận song song: Sân 1 (Bảng A): Đội 4 (KV Đặng Thùy Trâm/Phạm Tuấn Tài 3/Láng Hạ/Mê Linh) vs Đội 5 (KV Trần Quốc Vượng/Xuân Thủy/Hoàng Quốc Việt/Bắc Từ Liêm) Sân 2 (Bảng B): Đội 1 (Trụ sở – Khối Sản xuất - Vận hành) vs Đội 2 (Trụ sở – Khối Quản trị) Sân 3 (Bảng C): Đội 3 (Trụ sở – Khối TNKH & Truyền thông Marketing) vs Đội 8 (KV Thái Hà/Xuân Quỳnh/Tam Khương...) Sân 4 (Bảng D): Đội 7 (KV Văn Quán 1/Nguyễn Khuyến/Lê Thanh Nghị HD) vs Đội 11 (KV Phùng Khoang/Bắc Sơn/MonBay/Hoàng Diệu/Phong Châu) | D8: ='Timeline (5W1H)'!B10 | E8: ='Timeline (5W1H)'!C10 | F8: Thông báo kết thúc vòng bảng Bóng né, mời di chuyển | G8: 4 trọng tài chính bấm giờ 10 phút/sân, xử lý loại người, công bố kết quả. Trước trận: 2 đội oẳn tù xì chọn đội ném trước; sau đó trọng tài lần lượt đến từng đội (đứng quây vòng tròn kín, đối phương không nhìn thấy) để báo bí mật ai là Nữ hoàng của đội mình. | H8: Nhận kết quả từ 4 trọng tài, nhập ngay vào 'Nhập kết quả' | I8: Từ phút thứ 7, dẫn 12 đội di chuyển dần sang khu kéo co
A9: 5 | B9: Chuyển khu vực | C9: Di chuyển sang khu kéo co, phát nước | D9: ='Timeline (5W1H)'!B11 | E9: ='Timeline (5W1H)'!C11 | F9: Giữ nhịp bằng nhạc nền, thông báo di chuyển | G9: Di chuyển sang vị trí Dây 1–3, kiểm tra dây kéo co | H9: Rà soát lại đã nhập đủ 12 trận vòng bảng Bóng né | I9: Hướng dẫn theo màu đội; xác nhận đội Lượt 1 Kéo co vào vị trí | J9: Dây kéo co dựng sẵn trước giờ
A10: 6 | B10: Kéo co — Lượt 1 | C10: Vòng bảng Lượt 1, 3 trận song song. Dây 1: Bảng A (vòng 1) — Dây 2: Bảng B (vòng 1) — Dây 3: Bảng C (vòng 1) | D10: ='Timeline (5W1H)'!B12 | E10: ='Timeline (5W1H)'!C12 | F10: Giới thiệu nhanh cặp đấu từng dây qua loa | G10: 3 trọng tài chính bấm giờ 10 phút/dây, áp dụng luật dừng cứng khi hết giờ | H10: Nhận kết quả từ 3 trọng tài, nhập ngay vào 'Nhập kết quả' | I10: Từ phút thứ 7, xác nhận các đội của Lượt 2 đã có mặt tại vị trí chờ
A11: 7 | B11: Kéo co — Lượt 2 | C11: Vòng bảng Lượt 2, 3 trận song song. Dây 1: Bảng D (vòng 1) — Dây 2: Bảng A (vòng 2) — Dây 3: Bảng B (vòng 2) | D11: ='Timeline (5W1H)'!B13 | E11: ='Timeline (5W1H)'!C13 | F11: Giới thiệu nhanh cặp đấu từng dây qua loa | G11: 3 trọng tài chính bấm giờ 10 phút/dây, áp dụng luật dừng cứng khi hết giờ | H11: Nhận kết quả từ 3 trọng tài, nhập ngay vào 'Nhập kết quả' | I11: Từ phút thứ 7, xác nhận các đội của Lượt 3 đã có mặt tại vị trí chờ
A12: 8 | B12: Kéo co — Lượt 3 | C12: Vòng bảng Lượt 3, 3 trận song song. Dây 1: Bảng C (vòng 2) — Dây 2: Bảng D (vòng 2) — Dây 3: Bảng A (vòng 3) | D12: ='Timeline (5W1H)'!B14 | E12: ='Timeline (5W1H)'!C14 | F12: Giới thiệu nhanh cặp đấu từng dây qua loa | G12: 3 trọng tài chính bấm giờ 10 phút/dây, áp dụng luật dừng cứng khi hết giờ | H12: Nhận kết quả từ 3 trọng tài, nhập ngay vào 'Nhập kết quả' | I12: Từ phút thứ 7, xác nhận các đội của Lượt 4 đã có mặt tại vị trí chờ
A13: 9 | B13: Kéo co — Lượt 4 | C13: Vòng bảng Lượt 4, 3 trận song song. Dây 1: Bảng B (vòng 3) — Dây 2: Bảng C (vòng 3) — Dây 3: Bảng D (vòng 3) | D13: ='Timeline (5W1H)'!B15 | E13: ='Timeline (5W1H)'!C15 | F13: Thông báo kết thúc vòng bảng, mời nghỉ ngắn | G13: 3 trọng tài chính bấm giờ 10 phút/dây, áp dụng luật dừng cứng khi hết giờ | H13: Nhận kết quả từ 3 trọng tài, nhập ngay vào 'Nhập kết quả' | I13: Thông báo nghỉ giải lao ngắn tại chỗ, chờ tổng hợp
A14: 10 | B14: Tổng hợp vòng bảng | C14: Chốt bảng xếp hạng vòng bảng cả 2 môn, xác định đội vào bán kết | D14: ='Timeline (5W1H)'!B16 | E14: ='Timeline (5W1H)'!C16 | F14: Giao lưu / minigame khán giả giữ nhịp trong lúc chờ | G14: Nghỉ ngắn, di chuyển vào vị trí Sân 1–2 / Dây 1–2 (bán kết) | H14: Nhập nốt kết quả lượt cuối; xem tự động sheet 'Tổng kết' mục 1, xác nhận danh sách bán kết | I14: Chuẩn bị nước, khăn cho các đội nghỉ giải lao
A15: 11 | B15: Bóng né — Bán kết | C15: BK1: Nhất bảng A vs Nhất bảng B; BK2: Nhất bảng C vs Nhất bảng D | D15: ='Timeline (5W1H)'!B17 | E15: ='Timeline (5W1H)'!C17 | F15: Tường thuật trực tiếp, tạo không khí | G15: 2 trọng tài (Sân 1–2) bấm giờ 10 phút, xử lý tình huống. Trước trận: 2 đội oẳn tù xì chọn đội ném trước; sau đó trọng tài lần lượt đến từng đội (đứng quây vòng tròn kín, đối phương không nhìn thấy) để báo bí mật ai là Nữ hoàng của đội mình. | H15: Nhập kết quả bán kết ngay khi kết thúc | I15: Từ phút thứ 7, xác nhận đội bán kết Kéo co đã có mặt tại khu kéo co
A16: 12 | B16: Kéo co — Bán kết | C16: BK1: Nhất bảng A vs Nhất bảng B; BK2: Nhất bảng C vs Nhất bảng D | D16: ='Timeline (5W1H)'!B18 | E16: ='Timeline (5W1H)'!C18 | F16: Tường thuật trực tiếp | G16: 2 trọng tài (Dây 1–2) bấm giờ 10 phút | H16: Nhập kết quả bán kết ngay khi kết thúc | I16: Thông báo nghỉ ngắn tại chỗ, chờ tổng hợp kết quả bán kết
A17: 13 | B17: Tổng hợp bán kết | C17: Chốt kết quả bán kết cả 2 môn, xác định đội vào chung kết | D17: ='Timeline (5W1H)'!B19 | E17: ='Timeline (5W1H)'!C19 | F17: Hâm nóng không khí, mời khán giả tập trung quanh sân trung tâm | G17: Di chuyển về Sân 1 / Dây 1 (vị trí chung kết) | H17: Xem tự động sheet 'Tổng kết' mục 3, xác nhận danh sách chung kết | I17: Ổn định khán giả quanh khu vực sân trung tâm
A18: 14 | B18: Bóng né — Chung kết | C18: Chung kết Bóng né | D18: ='Timeline (5W1H)'!B20 | E18: ='Timeline (5W1H)'!C20 | F18: Tường thuật trực tiếp cao trào | G18: 1 trọng tài chính Sân 1 bấm giờ 10 phút. Trước trận: 2 đội oẳn tù xì chọn đội ném trước; sau đó trọng tài lần lượt đến từng đội (đứng quây vòng tròn kín, đối phương không nhìn thấy) để báo bí mật ai là Nữ hoàng của đội mình. | H18: Nhập kết quả chung kết Bóng né ngay khi kết thúc | I18: Từ phút thứ 7, xác nhận đội chung kết Kéo co đã sẵn sàng
A19: 15 | B19: Kéo co — Chung kết | C19: Chung kết Kéo co | D19: ='Timeline (5W1H)'!B21 | E19: ='Timeline (5W1H)'!C21 | F19: Tường thuật trực tiếp, khuấy động khán giả 2 bên | G19: 1 trọng tài chính Dây 1 bấm giờ 10 phút | H19: Nhập kết quả chung kết Kéo co | I19: Hỗ trợ khán giả, giữ trật tự quanh khu vực dây
A20: 16 | B20: Tổng hợp & chuẩn bị khen thưởng | C20: Chốt vô địch 2 môn; chuẩn bị bằng khen, cúp, phần thưởng đúng thứ tự | D20: ='Timeline (5W1H)'!B22 | E20: ='Timeline (5W1H)'!C22 | F20: Nhận danh sách xếp hạng cuối từ thư ký, chuẩn bị kịch bản xướng tên | G20: Bàn giao biên bản trận đấu cho BTC | H20: Chốt danh sách từ sheet 'Tổng kết', bàn giao cho bộ phận khen thưởng | I20: Xếp bằng khen/cúp đúng thứ tự MC sẽ xướng tên, kiểm đếm đủ số lượng | J20: Bằng khen, cúp, phần thưởng
A21: 17 | B21: Trao giải | C21: Trao giải Vô địch Bóng né, Vô địch Kéo co + chụp ảnh lưu niệm | D21: ='Timeline (5W1H)'!B23 | E21: ='Timeline (5W1H)'!C23 | F21: Xướng tên đúng thứ tự đã chuẩn bị, dẫn dắt lễ trao giải | G21: Hỗ trợ chung, đứng dự phòng | H21: Lưu trữ toàn bộ biên bản, xuất file kết quả cuối cùng | I21: Hỗ trợ đội lên sân khấu, hỗ trợ chụp ảnh
A22: 18 | B22: Dự phòng | C22: Xử lý phát sinh (trễ giờ, thời tiết, sự cố kỹ thuật) | D22: ='Timeline (5W1H)'!B24 | E22: ='Timeline (5W1H)'!C24 | F22: Chờ lệnh BTC | G22: Chờ lệnh BTC | H22: Chờ lệnh BTC | I22: Chờ lệnh BTC

Sheet Kịch bản 2 sân (dự phòng)
A1: KỊCH BẢN DỰ PHÒNG — 2 SÂN BÓNG NÉ (1 LƯỢT = 2 TRẬN SONG SONG)
A2: Dùng nếu venue CHỈ bố trí được 2 sân bóng né thay vì 4 sân như kế hoạch chính. Vòng bảng Bóng né cần 6 lượt (thay vì 3) — toàn chương trình kéo dài thêm ~30 phút so với bản chính (4 sân). Kéo co giữ nguyên 3 dây như bản chính.
A3: Sheet này ĐỘC LẬP với hệ thống chính (không liên kết Lịch thi đấu/Nhập kết quả) — chỉ dùng để tham khảo/in kịch bản nếu phải lùi về phương án 2 sân.
A5: STT | B5: Tiết mục | C5: Công việc chi tiết | D5: Bắt đầu | E5: Kết thúc | F5: MC | G5: Trọng tài | H5: Thư ký ghi kết quả | I5: Người hỗ trợ (TNV)
A6: 1 | B6: Khai mạc | C6: Khai mạc chớp nhoáng, phổ biến luật 2 môn | D6: =D7-10/1440 | E6: =D6+10/1440 | F6: Dẫn dắt khai mạc, phổ biến luật; phát tờ luật in sẵn cho 12 đội trưởng | G6: 5 trọng tài (2 sân Bóng né + 3 dây Kéo co) tập trung nhận sơ đồ vị trí, đồng bộ đồng hồ | H6: Chuẩn bị file kết quả, kiểm tra máy tính/kết nối mạng | I6: Từ phút thứ 7, đưa các đội của Lượt 1 Bóng né vào đúng sân
A7: 2 | B7: Bóng né — Lượt 1 | C7: Vòng bảng Lượt 1, 2 trận song song: Sân 1 (Bảng A): Đội 10 (KV Yên Nghĩa/Văn Quán 2-3) vs Đội 4 (KV Đặng Thùy Trâm/Phạm Tuấn Tài 3/Láng Hạ/Mê Linh) Sân 2 (Bảng C): Đội 9 (KV Thanh Trì/Trần Đại Nghĩa 2/Lê Duẩn HP/Lạch Tray HP) vs Đội 3 (Trụ sở – Khối TNKH & Truyền thông Marketing) | D7: 10:15 | E7: =D7+10/1440 | F7: Giới thiệu nhanh cặp đấu từng sân qua loa | G7: 2 trọng tài chính bấm giờ 10 phút/sân, xử lý loại người, công bố kết quả. Trước trận: 2 đội oẳn tù xì chọn đội ném trước; sau đó trọng tài lần lượt đến từng đội (đứng quây vòng tròn kín, đối phương không nhìn thấy) để báo bí mật ai là Nữ hoàng của đội mình. | H7: Nhận kết quả từ 2 trọng tài, nhập ngay | I7: Từ phút thứ 7, xác nhận các đội của Lượt 2 đã có mặt tại khu chờ đúng sân
A8: 3 | B8: Bóng né — Lượt 2 | C8: Vòng bảng Lượt 2, 2 trận song song: Sân 1 (Bảng B): Đội 12 (KV Gia Lâm/Giải Phóng/Lê Thanh Nghị 2) vs Đội 1 (Trụ sở – Khối Sản xuất - Vận hành) Sân 2 (Bảng D): Đội 6 (KV Nguyễn Khuyến 1/Quang Trung/Văn Phú) vs Đội 7 (KV Văn Quán 1/Nguyễn Khuyến/Lê Thanh Nghị HD) | D8: =E7 | E8: =D8+10/1440 | F8: Giới thiệu nhanh cặp đấu từng sân qua loa | G8: 2 trọng tài chính bấm giờ 10 phút/sân, xử lý loại người, công bố kết quả. Trước trận: 2 đội oẳn tù xì chọn đội ném trước; sau đó trọng tài lần lượt đến từng đội (đứng quây vòng tròn kín, đối phương không nhìn thấy) để báo bí mật ai là Nữ hoàng của đội mình. | H8: Nhận kết quả từ 2 trọng tài, nhập ngay | I8: Từ phút thứ 7, xác nhận các đội của Lượt 3 đã có mặt tại khu chờ đúng sân
A9: 4 | B9: Bóng né — Lượt 3 | C9: Vòng bảng Lượt 3, 2 trận song song: Sân 1 (Bảng A): Đội 10 (KV Yên Nghĩa/Văn Quán 2-3) vs Đội 5 (KV Trần Quốc Vượng/Xuân Thủy/Hoàng Quốc Việt/Bắc Từ Liêm) Sân 2 (Bảng C): Đội 9 (KV Thanh Trì/Trần Đại Nghĩa 2/Lê Duẩn HP/Lạch Tray HP) vs Đội 8 (KV Thái Hà/Xuân Quỳnh/Tam Khương...) | D9: =E8 | E9: =D9+10/1440 | F9: Giới thiệu nhanh cặp đấu từng sân qua loa | G9: 2 trọng tài chính bấm giờ 10 phút/sân, xử lý loại người, công bố kết quả. Trước trận: 2 đội oẳn tù xì chọn đội ném trước; sau đó trọng tài lần lượt đến từng đội (đứng quây vòng tròn kín, đối phương không nhìn thấy) để báo bí mật ai là Nữ hoàng của đội mình. | H9: Nhận kết quả từ 2 trọng tài, nhập ngay | I9: Từ phút thứ 7, xác nhận các đội của Lượt 4 đã có mặt tại khu chờ đúng sân
A10: 5 | B10: Bóng né — Lượt 4 | C10: Vòng bảng Lượt 4, 2 trận song song: Sân 1 (Bảng B): Đội 12 (KV Gia Lâm/Giải Phóng/Lê Thanh Nghị 2) vs Đội 2 (Trụ sở – Khối Quản trị) Sân 2 (Bảng D): Đội 6 (KV Nguyễn Khuyến 1/Quang Trung/Văn Phú) vs Đội 11 (KV Phùng Khoang/Bắc Sơn/MonBay/Hoàng Diệu/Phong Châu) | D10: =E9 | E10: =D10+10/1440 | F10: Giới thiệu nhanh cặp đấu từng sân qua loa | G10: 2 trọng tài chính bấm giờ 10 phút/sân, xử lý loại người, công bố kết quả. Trước trận: 2 đội oẳn tù xì chọn đội ném trước; sau đó trọng tài lần lượt đến từng đội (đứng quây vòng tròn kín, đối phương không nhìn thấy) để báo bí mật ai là Nữ hoàng của đội mình. | H10: Nhận kết quả từ 2 trọng tài, nhập ngay | I10: Từ phút thứ 7, xác nhận các đội của Lượt 5 đã có mặt tại khu chờ đúng sân
A11: 6 | B11: Bóng né — Lượt 5 | C11: Vòng bảng Lượt 5, 2 trận song song: Sân 1 (Bảng A): Đội 4 (KV Đặng Thùy Trâm/Phạm Tuấn Tài 3/Láng Hạ/Mê Linh) vs Đội 5 (KV Trần Quốc Vượng/Xuân Thủy/Hoàng Quốc Việt/Bắc Từ Liêm) Sân 2 (Bảng C): Đội 3 (Trụ sở – Khối TNKH & Truyền thông Marketing) vs Đội 8 (KV Thái Hà/Xuân Quỳnh/Tam Khương...) | D11: =E10 | E11: =D11+10/1440 | F11: Giới thiệu nhanh cặp đấu từng sân qua loa | G11: 2 trọng tài chính bấm giờ 10 phút/sân, xử lý loại người, công bố kết quả. Trước trận: 2 đội oẳn tù xì chọn đội ném trước; sau đó trọng tài lần lượt đến từng đội (đứng quây vòng tròn kín, đối phương không nhìn thấy) để báo bí mật ai là Nữ hoàng của đội mình. | H11: Nhận kết quả từ 2 trọng tài, nhập ngay | I11: Từ phút thứ 7, xác nhận các đội của Lượt 6 đã có mặt tại khu chờ đúng sân
A12: 7 | B12: Bóng né — Lượt 6 | C12: Vòng bảng Lượt 6, 2 trận song song: Sân 1 (Bảng B): Đội 1 (Trụ sở – Khối Sản xuất - Vận hành) vs Đội 2 (Trụ sở – Khối Quản trị) Sân 2 (Bảng D): Đội 7 (KV Văn Quán 1/Nguyễn Khuyến/Lê Thanh Nghị HD) vs Đội 11 (KV Phùng Khoang/Bắc Sơn/MonBay/Hoàng Diệu/Phong Châu) | D12: =E11 | E12: =D12+10/1440 | F12: Thông báo kết thúc vòng bảng Bóng né, mời di chuyển | G12: 2 trọng tài chính bấm giờ 10 phút/sân, xử lý loại người, công bố kết quả. Trước trận: 2 đội oẳn tù xì chọn đội ném trước; sau đó trọng tài lần lượt đến từng đội (đứng quây vòng tròn kín, đối phương không nhìn thấy) để báo bí mật ai là Nữ hoàng của đội mình. | H12: Nhận kết quả từ 2 trọng tài, nhập ngay | I12: Từ phút thứ 7, dẫn 12 đội di chuyển dần sang khu kéo co
A13: 8 | B13: Chuyển khu vực | C13: Di chuyển sang khu kéo co, phát nước | D13: =E12 | E13: =D13+10/1440 | F13: Giữ nhịp bằng nhạc nền, thông báo di chuyển | G13: Di chuyển sang vị trí Dây 1–3, kiểm tra dây kéo co | H13: Rà soát lại đã nhập đủ 12 trận vòng bảng Bóng né | I13: Hướng dẫn theo màu đội; xác nhận đội Lượt 1 Kéo co vào vị trí
A14: 9 | B14: Kéo co — Lượt 1 | C14: Vòng bảng Lượt 1, 3 trận song song: Dây 1 (Bảng A): Đội 10 (KV Yên Nghĩa/Văn Quán 2-3) vs Đội 4 (KV Đặng Thùy Trâm/Phạm Tuấn Tài 3/Láng Hạ/Mê Linh) Dây 2 (Bảng B): Đội 12 (KV Gia Lâm/Giải Phóng/Lê Thanh Nghị 2) vs Đội 1 (Trụ sở – Khối Sản xuất - Vận hành) Dây 3 (Bảng C): Đội 9 (KV Thanh Trì/Trần Đại Nghĩa 2/Lê Duẩn HP/Lạch Tray HP) vs Đội 3 (Trụ sở – Khối TNKH & Truyền thông Marketing) | D14: =E13 | E14: =D14+10/1440 | F14: Giới thiệu nhanh cặp đấu từng dây qua loa | G14: 3 trọng tài chính bấm giờ 10 phút/dây, áp dụng luật dừng cứng khi hết giờ | H14: Nhận kết quả từ 3 trọng tài, nhập ngay | I14: Từ phút thứ 7, xác nhận các đội của Lượt 2 đã có mặt tại vị trí chờ
A15: 10 | B15: Kéo co — Lượt 2 | C15: Vòng bảng Lượt 2, 3 trận song song: Dây 1 (Bảng D): Đội 6 (KV Nguyễn Khuyến 1/Quang Trung/Văn Phú) vs Đội 7 (KV Văn Quán 1/Nguyễn Khuyến/Lê Thanh Nghị HD) Dây 2 (Bảng A): Đội 10 (KV Yên Nghĩa/Văn Quán 2-3) vs Đội 5 (KV Trần Quốc Vượng/Xuân Thủy/Hoàng Quốc Việt/Bắc Từ Liêm) Dây 3 (Bảng B): Đội 12 (KV Gia Lâm/Giải Phóng/Lê Thanh Nghị 2) vs Đội 2 (Trụ sở – Khối Quản trị) | D15: =E14 | E15: =D15+10/1440 | F15: Giới thiệu nhanh cặp đấu từng dây qua loa | G15: 3 trọng tài chính bấm giờ 10 phút/dây, áp dụng luật dừng cứng khi hết giờ | H15: Nhận kết quả từ 3 trọng tài, nhập ngay | I15: Từ phút thứ 7, xác nhận các đội của Lượt 3 đã có mặt tại vị trí chờ
